<?xml version="1.0" ?>
<!-- =================================================================================== -->
<!-- |    This document was autogenerated by xacro from /home/yj/ros2_ws/install/my_robot_ros2_control/share/my_robot_ros2_control/description/urdf/my_robot.description.urdf.xacro | -->
<!-- |    EDITING THIS FILE BY HAND IS NOT RECOMMENDED                                 | -->
<!-- =================================================================================== -->
<robot name="my_robot">
  <!-- Materials -->
  <material name="robot_black">
    <color rgba="0.2 0.2 0.2 1"/>
  </material>
  <material name="robot_white">
    <color rgba="0.9 0.9 0.9 1"/>
  </material>
  <material name="robot_red">
    <color rgba="0.8 0.2 0.2 1"/>
  </material>
  <material name="robot_blue">
    <color rgba="0.2 0.4 0.8 1"/>
  </material>
  <material name="robot_green">
    <color rgba="0.2 0.8 0.2 1"/>
  </material>
  <material name="robot_yellow">
    <color rgba="0.9 0.9 0.1 1"/>
  </material>
  <material name="robot_orange">
    <color rgba="1.0 0.5 0.1 1"/>
  </material>
  <material name="robot_purple">
    <color rgba="0.6 0.2 0.8 1"/>
  </material>
  <!-- World Link -->
  <link name="world"/>
  <!-- Base Joint (connects world to robot) -->
  <joint name="base_joint" type="fixed">
    <origin rpy="0 0 0" xyz="0 0 0"/>
    <parent link="world"/>
    <child link="base_link"/>
  </joint>
  <link name="base_link">
    <collision name="mesh_base_link_collision">
      <origin rpy="0.0 0.0 0.0" xyz="0 0 0"/>
      <geometry>
        <mesh filename="package://my_robot_ros2_control/description/urdf/meshes/mesh_base_link.stl" scale="0.001 0.001 0.001"/>
        <!-- Add other geometry types as needed -->
      </geometry>
    </collision>
    <visual name="mesh_base_link">
      <material name="robot_black"/>
      <origin rpy="0.0 0.0 0.0" xyz="0 0 0"/>
      <geometry>
        <mesh filename="package://my_robot_ros2_control/description/urdf/meshes/mesh_base_link.stl" scale="0.001 0.001 0.001"/>
      </geometry>
    </visual>
  </link>
  <joint name="link1_motor_joint" type="fixed">
    <origin rpy="0 0 0" xyz="0 0 0.0263"/>
    <parent link="base_link"/>
    <child link="link1_motor"/>
  </joint>
  <link name="link1_motor">
    <collision name="mesh_link1_motor_collision">
      <origin rpy="0.0 0.0 0.0" xyz="0 0 -0.0263"/>
      <geometry>
        <mesh filename="package://my_robot_ros2_control/description/urdf/meshes/mesh_link1_motor.stl" scale="0.001 0.001 0.001"/>
        <!-- Add other geometry types as needed -->
      </geometry>
    </collision>
    <visual name="mesh_link1_motor">
      <material name="robot_red"/>
      <origin rpy="0.0 0.0 0.0" xyz="0 0 -0.0263"/>
      <geometry>
        <mesh filename="package://my_robot_ros2_control/description/urdf/meshes/mesh_link1_motor.stl" scale="0.001 0.001 0.001"/>
      </geometry>
    </visual>
  </link>
  <joint name="link1_1_joint" type="revolute">
    <limit effort="0.0" lower="-3.6651914291883334" upper="0.5235987755983333" velocity="2.408554367752333"/>
    <origin rpy="0 0 0" xyz="0 0 0.0507"/>
    <parent link="link1_motor"/>
    <child link="link1_1"/>
    <axis xyz="0 0 1"/>
  </joint>
  <link name="link1_1">
    <collision name="mesh_link1_1_collision">
      <origin rpy="0.0 0.0 0.0" xyz="0 0 -0.077"/>
      <geometry>
        <mesh filename="package://my_robot_ros2_control/description/urdf/meshes/mesh_link1_1.stl" scale="0.001 0.001 0.001"/>
        <!-- Add other geometry types as needed -->
      </geometry>
    </collision>
    <visual name="mesh_link1_1">
      <material name="robot_blue"/>
      <origin rpy="0.0 0.0 0.0" xyz="0 0 -0.077"/>
      <geometry>
        <mesh filename="package://my_robot_ros2_control/description/urdf/meshes/mesh_link1_1.stl" scale="0.001 0.001 0.001"/>
      </geometry>
    </visual>
  </link>
  <joint name="link1_2_joint" type="fixed">
    <origin rpy="0 0 0" xyz="0 0 0.015"/>
    <parent link="link1_1"/>
    <child link="link1_2"/>
  </joint>
  <link name="link1_2">
    <collision name="mesh_link1_2_collision">
      <origin rpy="0.0 0.0 0.0" xyz="0 0 -0.092"/>
      <geometry>
        <mesh filename="package://my_robot_ros2_control/description/urdf/meshes/mesh_link1_2.stl" scale="0.001 0.001 0.001"/>
        <!-- Add other geometry types as needed -->
      </geometry>
    </collision>
    <visual name="mesh_link1_2">
      <material name="robot_white"/>
      <origin rpy="0.0 0.0 0.0" xyz="0 0 -0.092"/>
      <geometry>
        <mesh filename="package://my_robot_ros2_control/description/urdf/meshes/mesh_link1_2.stl" scale="0.001 0.001 0.001"/>
      </geometry>
    </visual>
  </link>
  <joint name="link2_motor_joint" type="fixed">
    <origin rpy="0 0 0" xyz="0 0 0.059"/>
    <parent link="link1_2"/>
    <child link="link2_motor"/>
  </joint>
  <link name="link2_motor">
    <collision name="mesh_link2_motor_collision">
      <origin rpy="0.0 0.0 0.0" xyz="0 0 -0.151"/>
      <geometry>
        <mesh filename="package://my_robot_ros2_control/description/urdf/meshes/mesh_link2_motor.stl" scale="0.001 0.001 0.001"/>
        <!-- Add other geometry types as needed -->
      </geometry>
    </collision>
    <visual name="mesh_link2_motor">
      <material name="robot_red"/>
      <origin rpy="0.0 0.0 0.0" xyz="0 0 -0.151"/>
      <geometry>
        <mesh filename="package://my_robot_ros2_control/description/urdf/meshes/mesh_link2_motor.stl" scale="0.001 0.001 0.001"/>
      </geometry>
    </visual>
  </link>
  <joint name="link2_1_joint" type="revolute">
    <limit effort="0.0" lower="-1.570796326795" upper="1.570796326795" velocity="2.408554367752333"/>
    <origin rpy="0 0 0" xyz="0.009 0 0"/>
    <parent link="link2_motor"/>
    <child link="link2_1"/>
    <axis xyz="1 0 0"/>
  </joint>
  <link name="link2_1">
    <collision name="mesh_link2_1_collision">
      <origin rpy="0.0 0.0 0.0" xyz="-0.009 0 -0.151"/>
      <geometry>
        <mesh filename="package://my_robot_ros2_control/description/urdf/meshes/mesh_link2_1.stl" scale="0.001 0.001 0.001"/>
        <!-- Add other geometry types as needed -->
      </geometry>
    </collision>
    <visual name="mesh_link2_1">
      <material name="robot_green"/>
      <origin rpy="0.0 0.0 0.0" xyz="-0.009 0 -0.151"/>
      <geometry>
        <mesh filename="package://my_robot_ros2_control/description/urdf/meshes/mesh_link2_1.stl" scale="0.001 0.001 0.001"/>
      </geometry>
    </visual>
  </link>
  <joint name="link2_2_joint" type="fixed">
    <origin rpy="0 0 0" xyz="0.015 0 0"/>
    <parent link="link2_1"/>
    <child link="link2_2"/>
  </joint>
  <link name="link2_2">
    <collision name="mesh_link2_2_collision">
      <origin rpy="0.0 0.0 0.0" xyz="-0.024 0 -0.151"/>
      <geometry>
        <mesh filename="package://my_robot_ros2_control/description/urdf/meshes/mesh_link2_PLA.stl" scale="0.001 0.001 0.001"/>
        <!-- Add other geometry types as needed -->
      </geometry>
    </collision>
    <visual name="mesh_link2_2">
      <material name="robot_white"/>
      <origin rpy="0.0 0.0 0.0" xyz="-0.024 0 -0.151"/>
      <geometry>
        <mesh filename="package://my_robot_ros2_control/description/urdf/meshes/mesh_link2_PLA.stl" scale="0.001 0.001 0.001"/>
      </geometry>
    </visual>
  </link>
  <joint name="link2_3_joint" type="fixed">
    <origin rpy="0 0 0" xyz="0.075 0 0.13"/>
    <parent link="link2_2"/>
    <child link="link2_3"/>
  </joint>
  <link name="link2_3">
    <collision name="mesh_link2_3_collision">
      <origin rpy="0.0 0.0 0.0" xyz="-0.099 0 -0.281"/>
      <geometry>
        <mesh filename="package://my_robot_ros2_control/description/urdf/meshes/mesh_link2_7.stl" scale="0.001 0.001 0.001"/>
        <!-- Add other geometry types as needed -->
      </geometry>
    </collision>
    <visual name="mesh_link2_3">
      <material name="robot_yellow"/>
      <origin rpy="0.0 0.0 0.0" xyz="-0.099 0 -0.281"/>
      <geometry>
        <mesh filename="package://my_robot_ros2_control/description/urdf/meshes/mesh_link2_7.stl" scale="0.001 0.001 0.001"/>
      </geometry>
    </visual>
  </link>
  <joint name="link3_motor_joint" type="fixed">
    <origin rpy="0 0 0" xyz="0 0 0.021"/>
    <parent link="link2_3"/>
    <child link="link3_motor"/>
  </joint>
  <link name="link3_motor">
    <collision name="mesh_link3_motor_collision">
      <origin rpy="0.0 0.0 0.0" xyz="-0.099 0 -0.302"/>
      <geometry>
        <mesh filename="package://my_robot_ros2_control/description/urdf/meshes/mesh_link3_motor.stl" scale="0.001 0.001 0.001"/>
        <!-- Add other geometry types as needed -->
      </geometry>
    </collision>
    <visual name="mesh_link3_motor">
      <material name="robot_red"/>
      <origin rpy="0.0 0.0 0.0" xyz="-0.099 0 -0.302"/>
      <geometry>
        <mesh filename="package://my_robot_ros2_control/description/urdf/meshes/mesh_link3_motor.stl" scale="0.001 0.001 0.001"/>
      </geometry>
    </visual>
  </link>
  <joint name="link3_1_joint" type="revolute">
    <limit effort="0.0" lower="-4.0142572795872224" upper="1.0471975511966667" velocity="15.498523757710668"/>
    <origin rpy="0 0 0" xyz="0 0 0.03905"/>
    <parent link="link3_motor"/>
    <child link="link3_1"/>
    <axis xyz="0 0 1"/>
  </joint>
  <link name="link3_1">
    <collision name="mesh_link3_1_collision">
      <origin rpy="0.0 0.0 0.0" xyz="-0.099 0 -0.34105"/>
      <geometry>
        <mesh filename="package://my_robot_ros2_control/description/urdf/meshes/mesh_link3_1.stl" scale="0.001 0.001 0.001"/>
        <!-- Add other geometry types as needed -->
      </geometry>
    </collision>
    <visual name="mesh_link3_1">
      <material name="robot_orange"/>
      <origin rpy="0.0 0.0 0.0" xyz="-0.099 0 -0.34105"/>
      <geometry>
        <mesh filename="package://my_robot_ros2_control/description/urdf/meshes/mesh_link3_1.stl" scale="0.001 0.001 0.001"/>
      </geometry>
    </visual>
  </link>
  <joint name="link3_2_joint" type="fixed">
    <origin rpy="0 0 0" xyz="0 0 0.015"/>
    <parent link="link3_1"/>
    <child link="link3_2"/>
  </joint>
  <link name="link3_2">
    <collision name="mesh_link3_2_collision">
      <origin rpy="0.0 0.0 0.0" xyz="-0.099 0 -0.35605"/>
      <geometry>
        <mesh filename="package://my_robot_ros2_control/description/urdf/meshes/mesh_link3_2.stl" scale="0.001 0.001 0.001"/>
        <!-- Add other geometry types as needed -->
      </geometry>
    </collision>
    <visual name="mesh_link3_2">
      <material name="robot_purple"/>
      <origin rpy="0.0 0.0 0.0" xyz="-0.099 0 -0.35605"/>
      <geometry>
        <mesh filename="package://my_robot_ros2_control/description/urdf/meshes/mesh_link3_2.stl" scale="0.001 0.001 0.001"/>
      </geometry>
    </visual>
  </link>
  <joint name="link4_motor_joint" type="fixed">
    <origin rpy="0 0 0" xyz="0.004 0 0.0546"/>
    <parent link="link3_2"/>
    <child link="link4_motor"/>
  </joint>
  <link name="link4_motor">
    <collision name="mesh_link4_motor_collision">
      <origin rpy="0.0 0.0 0.0" xyz="-0.103 0 -0.41065"/>
      <geometry>
        <mesh filename="package://my_robot_ros2_control/description/urdf/meshes/mesh_link4_motor.stl" scale="0.001 0.001 0.001"/>
        <!-- Add other geometry types as needed -->
      </geometry>
    </collision>
    <visual name="mesh_link4_motor">
      <material name="robot_red"/>
      <origin rpy="0.0 0.0 0.0" xyz="-0.103 0 -0.41065"/>
      <geometry>
        <mesh filename="package://my_robot_ros2_control/description/urdf/meshes/mesh_link4_motor.stl" scale="0.001 0.001 0.001"/>
      </geometry>
    </visual>
  </link>
  <joint name="link4_1_joint" type="revolute">
    <limit effort="0.0" lower="-1.6580627893947222" upper="1.6580627893947222" velocity="15.498523757710668"/>
    <origin rpy="0 0 0" xyz="-0.0065 0 0"/>
    <parent link="link4_motor"/>
    <child link="link4_1"/>
    <axis xyz="-1 0 0"/>
  </joint>
  <link name="link4_1">
    <collision name="mesh_link4_1_collision">
      <origin rpy="0.0 0.0 0.0" xyz="-0.0965 0 -0.41065"/>
      <geometry>
        <mesh filename="package://my_robot_ros2_control/description/urdf/meshes/mesh_link4_1.stl" scale="0.001 0.001 0.001"/>
        <!-- Add other geometry types as needed -->
      </geometry>
    </collision>
    <visual name="mesh_link4_1">
      <material name="robot_blue"/>
      <origin rpy="0.0 0.0 0.0" xyz="-0.0965 0 -0.41065"/>
      <geometry>
        <mesh filename="package://my_robot_ros2_control/description/urdf/meshes/mesh_link4_1.stl" scale="0.001 0.001 0.001"/>
      </geometry>
    </visual>
  </link>
  <joint name="link4_2_joint" type="fixed">
    <origin rpy="0 0 0" xyz="-0.015 0 0"/>
    <parent link="link4_1"/>
    <child link="link4_2"/>
  </joint>
  <link name="link4_2">
    <collision name="mesh_link4_2_collision">
      <origin rpy="0.0 0.0 0.0" xyz="-0.0815 0 -0.41065"/>
      <geometry>
        <mesh filename="package://my_robot_ros2_control/description/urdf/meshes/mesh_link4_PLA.stl" scale="0.001 0.001 0.001"/>
        <!-- Add other geometry types as needed -->
      </geometry>
    </collision>
    <visual name="mesh_link4_2">
      <material name="robot_white"/>
      <origin rpy="0.0 0.0 0.0" xyz="-0.0815 0 -0.41065"/>
      <geometry>
        <mesh filename="package://my_robot_ros2_control/description/urdf/meshes/mesh_link4_PLA.stl" scale="0.001 0.001 0.001"/>
      </geometry>
    </visual>
  </link>
  <joint name="link4_3_joint" type="fixed">
    <origin rpy="0 0 0" xyz="-0.075 0 0.1"/>
    <parent link="link4_2"/>
    <child link="link4_3"/>
  </joint>
  <link name="link4_3">
    <collision name="mesh_link4_3_collision">
      <origin rpy="0.0 0.0 0.0" xyz="-0.0065 0 -0.51065"/>
      <geometry>
        <mesh filename="package://my_robot_ros2_control/description/urdf/meshes/mesh_link4_7.stl" scale="0.001 0.001 0.001"/>
        <!-- Add other geometry types as needed -->
      </geometry>
    </collision>
    <visual name="mesh_link4_3">
      <material name="robot_green"/>
      <origin rpy="0.0 0.0 0.0" xyz="-0.0065 0 -0.51065"/>
      <geometry>
        <mesh filename="package://my_robot_ros2_control/description/urdf/meshes/mesh_link4_7.stl" scale="0.001 0.001 0.001"/>
      </geometry>
    </visual>
  </link>
  <joint name="link5_motor_joint" type="fixed">
    <origin rpy="0 0 0" xyz="0 0 0.02"/>
    <parent link="link4_3"/>
    <child link="link5_motor"/>
  </joint>
  <link name="link5_motor">
    <collision name="mesh_link5_motor_collision">
      <origin rpy="0.0 0.0 0.0" xyz="-0.0065 0 -0.53065"/>
      <geometry>
        <mesh filename="package://my_robot_ros2_control/description/urdf/meshes/mesh_link5_motor.stl" scale="0.001 0.001 0.001"/>
        <!-- Add other geometry types as needed -->
      </geometry>
    </collision>
    <visual name="mesh_link5_motor">
      <material name="robot_red"/>
      <origin rpy="0.0 0.0 0.0" xyz="-0.0065 0 -0.53065"/>
      <geometry>
        <mesh filename="package://my_robot_ros2_control/description/urdf/meshes/mesh_link5_motor.stl" scale="0.001 0.001 0.001"/>
      </geometry>
    </visual>
  </link>
  <joint name="link5_1_joint" type="revolute">
    <limit effort="0.0" lower="-3.4906585039888887" upper="2.0943951023933334" velocity="24.399702942882335"/>
    <origin rpy="0 0 0" xyz="0 0 0.029"/>
    <parent link="link5_motor"/>
    <child link="link5_1"/>
    <axis xyz="0 0 1"/>
  </joint>
  <link name="link5_1">
    <collision name="mesh_link5_1_collision">
      <origin rpy="0.0 0.0 0.0" xyz="-0.0065 0 -0.55965"/>
      <geometry>
        <mesh filename="package://my_robot_ros2_control/description/urdf/meshes/mesh_link5_1.stl" scale="0.001 0.001 0.001"/>
        <!-- Add other geometry types as needed -->
      </geometry>
    </collision>
    <visual name="mesh_link5_1">
      <material name="robot_yellow"/>
      <origin rpy="0.0 0.0 0.0" xyz="-0.0065 0 -0.55965"/>
      <geometry>
        <mesh filename="package://my_robot_ros2_control/description/urdf/meshes/mesh_link5_1.stl" scale="0.001 0.001 0.001"/>
      </geometry>
    </visual>
  </link>
  <joint name="link5_2_joint" type="fixed">
    <origin rpy="0 0 0" xyz="0 0 0.02"/>
    <parent link="link5_1"/>
    <child link="link5_2"/>
  </joint>
  <link name="link5_2">
    <collision name="mesh_link5_2_collision">
      <origin rpy="0.0 0.0 0.0" xyz="-0.0065 0 -0.57965"/>
      <geometry>
        <mesh filename="package://my_robot_ros2_control/description/urdf/meshes/mesh_link5_2.stl" scale="0.001 0.001 0.001"/>
        <!-- Add other geometry types as needed -->
      </geometry>
    </collision>
    <visual name="mesh_link5_2">
      <material name="robot_orange"/>
      <origin rpy="0.0 0.0 0.0" xyz="-0.0065 0 -0.57965"/>
      <geometry>
        <mesh filename="package://my_robot_ros2_control/description/urdf/meshes/mesh_link5_2.stl" scale="0.001 0.001 0.001"/>
      </geometry>
    </visual>
  </link>
  <joint name="link6_motor_joint" type="fixed">
    <origin rpy="0 0 0" xyz="0.0035 0 0.04950"/>
    <parent link="link5_2"/>
    <child link="link6_motor"/>
  </joint>
  <link name="link6_motor">
    <collision name="mesh_link6_motor_collision">
      <origin rpy="0.0 0.0 0.0" xyz="-0.01 0 -0.62915"/>
      <geometry>
        <mesh filename="package://my_robot_ros2_control/description/urdf/meshes/mesh_link6_motor.stl" scale="0.001 0.001 0.001"/>
        <!-- Add other geometry types as needed -->
      </geometry>
    </collision>
    <visual name="mesh_link6_motor">
      <material name="robot_red"/>
      <origin rpy="0.0 0.0 0.0" xyz="-0.01 0 -0.62915"/>
      <geometry>
        <mesh filename="package://my_robot_ros2_control/description/urdf/meshes/mesh_link6_motor.stl" scale="0.001 0.001 0.001"/>
      </geometry>
    </visual>
  </link>
  <joint name="link6_1_joint" type="revolute">
    <limit effort="0.0" lower="-1.6580627893947222" upper="1.6580627893947222" velocity="24.399702942882335"/>
    <origin rpy="0 0 0" xyz="0.002 0 0"/>
    <parent link="link6_motor"/>
    <child link="link6_1"/>
    <axis xyz="1 0 0"/>
  </joint>
  <link name="link6_1">
    <collision name="mesh_link6_1_collision">
      <origin rpy="0.0 0.0 0.0" xyz="-0.012 0 -0.62915"/>
      <geometry>
        <mesh filename="package://my_robot_ros2_control/description/urdf/meshes/mesh_link6_1.stl" scale="0.001 0.001 0.001"/>
        <!-- Add other geometry types as needed -->
      </geometry>
    </collision>
    <visual name="mesh_link6_1">
      <material name="robot_purple"/>
      <origin rpy="0.0 0.0 0.0" xyz="-0.012 0 -0.62915"/>
      <geometry>
        <mesh filename="package://my_robot_ros2_control/description/urdf/meshes/mesh_link6_1.stl" scale="0.001 0.001 0.001"/>
      </geometry>
    </visual>
  </link>
</robot>
